Workbook

Sheet RAW_CRAWL
A1: Address | B1: Content Type | C1: Status Code | D1: Status | E1: Indexability | F1: Indexability Status | G1: Title 1 | H1: Title 1 Length | I1: Title 1 Pixel Width | J1: Meta Description 1 | K1: Meta Description 1 Length | L1: Meta Description 1 Pixel Width | M1: Meta Keywords 1 | N1: Meta Keywords 1 Length | O1: H1-1 | P1: H1-1 Length | Q1: H1-2 | R1: H1-2 Length | S1: H2-1 | T1: H2-1 Length | U1: H2-2 | V1: H2-2 Length | W1: Meta Robots 1 | X1: X-Robots-Tag 1 | Y1: Meta Refresh 1 | Z1: Canonical Link Element 1 | AA1: rel="next" 1 | AB1: rel="prev" 1 | AC1: HTTP rel="next" 1 | AD1: HTTP rel="prev" 1 | AE1: amphtml Link Element | AF1: Size (bytes) | AG1: Transferred (bytes) | AH1: Total Transferred (bytes) | AI1: CO2 (mg) | AJ1: Carbon Rating | AK1: Word Count | AL1: Sentence Count | AM1: Average Words Per Sentence | AN1: Flesch Reading Ease Score | AO1: Readability | AP1: Text Ratio | AQ1: Crawl Depth | AR1: Folder Depth | AS1: Link Score | AT1: Inlinks | AU1: Unique Inlinks | AV1: Unique JS Inlinks | AW1: % of Total | AX1: Outlinks | AY1: Unique Outlinks | AZ1: Unique JS Outlinks | BA1: External Outlinks | BB1: Unique External Outlinks | BC1: Unique External JS Outlinks | BD1: Closest Similarity Match | BE1: No. Near Duplicates | BF1: Spelling Errors | BG1: Grammar Errors | BH1: Hash | BI1: Response Time | BJ1: Last Modified | BK1: Redirect URL | BL1: Redirect Type | BM1: Cookies | BN1: Language | BO1: HTTP Version | BP1: Mobile Alternate Link | BQ1: URL Encoded Address | BR1: Crawl Timestamp
A2: https://pmb.widyatama.ac.id/ | B2: text/html; charset=UTF-8 | C2: 200 | E2: Indexable | G2: Home - PMB UTama | H2: 16 | I2: 182 | K2: 0 | L2: 0 | N2: 0 | O2: Penerimaan Mahasiswa Baru Universitas Widyatama Bandung | P2: 55 | R2: 0 | S2: Temukan Jalur Kuliah yang Paling Sesuai | T2: 39 | U2: Program Studi Diploma, Sarjana, dan Pascasarjana | V2: 48 | W2: index, follow, max-image-preview:large, max-snippet:-1, max-video-preview:-1 | Z2: https://pmb.widyatama.ac.id/ | AF2: 222241 | AG2: 46607 | AH2: 37100272 | AI2: 13152232 | AJ2: F | AK2: 961 | AL2: 199 | AM2: 4829 | AN2: 0.000 | AO2: Very Hard | AP2: 3528 | AQ2: 0 | AR2: 0 | AT2: 466 | AU2: 77 | AV2: 77 | AW2: 88510 | AX2: 128 | AY2: 32 | AZ2: 0 | BA2: 21 | BB2: 12 | BC2: 4 | BH2: a20e81bc6438e5cebb62cebec82d43c2 | BI2: 3290 | BJ2: Saturday, 15-Aug-2026 09:54:51 GMT | BN2: en-US | BO2: 2.0 | BQ2: https://pmb.widyatama.ac.id/ | BR2: 46249.705
A3: https://pmb.widyatama.ac.id/wp-content/plugins/popup-maker/dist/packages/block-library-style.css?ver=7424eb959f91acb8bbb2 | B3: text/html; charset=UTF-8 | C3: 404 | D3: Aborted | E3: Non-Indexable | F3: Client Error | H3: 0 | I3: 0 | K3: 0 | L3: 0 | N3: 0 | P3: 0 | R3: 0 | T3: 0 | V3: 0 | AF3: 0 | AG3: 0 | AH3: 0 | AI3: 0.000 | AJ3: A+ | AK3: 0 | AP3: 0.000 | AQ3: 1 | AR3: 5 | AT3: 0 | AU3: 0 | AV3: 0 | AW3: 0.000 | AX3: 0 | AY3: 0 | AZ3: 0 | BA3: 0 | BB3: 0 | BC3: 0 | BI3: 21137 | BQ3: https://pmb.widyatama.ac.id/wp-content/plugins/popup-maker/dist/packages/block-library-style.css?ver=7424eb959f91acb8bbb2 | BR3: 46249.705
A4: https://pmb.widyatama.ac.id/cdn-cgi/l/email-protection | B4: text/html | C4: 404 | E4: Non-Indexable | F4: Client Error | H4: 0 | I4: 0 | K4: 0 | L4: 0 | N4: 0 | P4: 0 | R4: 0 | T4: 0 | V4: 0 | AF4: 4741 | AG4: 2125 | AH4: 6745 | AI4: 2391 | AJ4: A+ | AK4: 0 | AP4: 0.000 | AQ4: 1 | AR4: 2 | AT4: 9 | AU4: 3 | AV4: 0 | AW4: 3450 | AX4: 0 | AY4: 0 | AZ4: 0 | BA4: 0 | BB4: 0 | BC4: 0 | BI4: 0.205 | BO4: 2.0 | BQ4: https://pmb.widyatama.ac.id/cdn-cgi/l/email-protection | BR4: 46249.705
A5: https://pmb.widyatama.ac.id/sitemap/ | B5: text/html; charset=UTF-8 | C5: 404 | E5: Non-Indexable | F5: Client Error | H5: 0 | I5: 0 | K5: 0 | L5: 0 | N5: 0 | P5: 0 | R5: 0 | T5: 0 | V5: 0 | AF5: 120598 | AG5: 28660 | AH5: 898177 | AI5: 318408 | AJ5: B | AK5: 0 | AP5: 0.000 | AQ5: 1 | AR5: 1 | AT5: 77 | AU5: 77 | AV5: 0 | AW5: 88510 | AX5: 0 | AY5: 0 | AZ5: 0 | BA5: 0 | BB5: 0 | BC5: 0 | BI5: 3024 | BO5: 2.0 | BQ5: https://pmb.widyatama.ac.id/sitemap/ | BR5: 46249.705
A6: https://pmb.widyatama.ac.id/usm-tpa/ | B6: text/html; charset=UTF-8 | C6: 404 | E6: Non-Indexable | F6: Client Error | H6: 0 | I6: 0 | K6: 0 | L6: 0 | N6: 0 | P6: 0 | R6: 0 | T6: 0 | V6: 0 | AF6: 120598 | AG6: 28666 | AH6: 898189 | AI6: 318412 | AJ6: B | AK6: 0 | AP6: 0.000 | AQ6: 1 | AR6: 1 | AT6: 1 | AU6: 1 | AV6: 0 | AW6: 1150 | AX6: 0 | AY6: 0 | AZ6: 0 | BA6: 0 | BB6: 0 | BC6: 0 | BI6: 3661 | BO6: 2.0 | BQ6: https://pmb.widyatama.ac.id/usm-tpa/ | BR6: 46249.705
A7: https://pmb.widyatama.ac.id/petunjuk-pendaftaran/ | B7: text/html; charset=UTF-8 | C7: 200 | E7: Indexable | G7: Petunjuk Pendaftaran - PMB UTama | H7: 32 | I7: 322 | K7: 0 | L7: 0 | N7: 0 | O7: Petunjuk Pendaftaran Mahasiswa Baru Universitas Widyatama | P7: 57 | R7: 0 | S7: Buat akun PMB lebih dulu, lalu ikuti setiap tahap dengan urut. | T7: 62 | U7: Cara Mudah Daftar Kuliah Online | V7: 31 | W7: index, follow, max-image-preview:large, max-snippet:-1, max-video-preview:-1 | Z7: https://pmb.widyatama.ac.id/petunjuk-pendaftaran/ | AF7: 175545 | AG7: 38335 | AH7: 3734312 | AI7: 1323832 | AJ7: F | AK7: 943 | AL7: 197 | AM7: 4787 | AN7: 13847 | AO7: Very Hard | AP7: 3382 | AQ7: 1 | AR7: 1 | AT7: 334 | AU7: 77 | AV7: 80 | AW7: 88510 | AX7: 139 | AY7: 30 | AZ7: 1 | BA7: 17 | BB7: 9 | BC7: 4 | BH7: a2d3f3de39b760ce0970219c23bc52b8 | BI7: 0.098 | BJ7: Saturday, 15-Aug-2026 09:55:42 GMT | BN7: en-US | BO7: None | BQ7: https://pmb.widyatama.ac.id/petunjuk-pendaftaran/ | BR7: 46249.705
A8: https://pmb.widyatama.ac.id/jenjang-pendidikan/ | B8: text/html; charset=UTF-8 | C8: 200 | E8: Indexable | G8: Jenjang Pendidikan - PMB UTama | H8: 30 | I8: 303 | K8: 0 | L8: 0 | N8: 0 | O8: Jenjang Pendidikan Universitas Widyatama: Diploma, Sarjana, Pascasarjana, dan Doktoral | P8: 86 | R8: 0 | S8: Konsultasi singkat untuk tahu jenjang yang paling sesuai. | T8: 57 | U8: Mana Jenjang yang Cocok Buatmu? | V8: 31 | W8: index, follow, max-image-preview:large, max-snippet:-1, max-video-preview:-1 | Z8: https://pmb.widyatama.ac.id/jenjang-pendidikan/ | AF8: 215138 | AG8: 46196 | AH8: 2434454 | AI8: 863026 | AJ8: F | AK8: 1532 | AL8: 289 | AM8: 5301 | AN8: 10221 | AO8: Very Hard | AP8: 4366 | AQ8: 1 | AR8: 1 | AT8: 332 | AU8: 77 | AV8: 76 | AW8: 88510 | AX8: 165 | AY8: 54 | AZ8: 0 | BA8: 23 | BB8: 13 | BC8: 8 | BH8: fe78e3bec59564785a59504aa8a6fc32 | BI8: 0.141 | BJ8: Saturday, 15-Aug-2026 09:55:44 GMT | BN8: en-US | BO8: 2.0 | BQ8: https://pmb.widyatama.ac.id/jenjang-pendidikan/ | BR8: 46249.705
A9: https://pmb.widyatama.ac.id/privacy-policy/ | B9: text/html; charset=UTF-8 | C9: 200 | E9: Indexable | G9: Privacy Policy - PMB UTama | H9: 26 | I9: 251 | K9: 0 | L9: 0 | N9: 0 | O9: Kebijakan Privasi Website PMB Universitas Widyatama | P9: 51 | R9: 0 | S9: Universitas Widyatama memproses data secara sah, terbatas, dan bertanggung jawab. | T9: 81 | U9: Empat Hal yang Perlu Anda Ketahui | V9: 33 | W9: index, follow, max-image-preview:large, max-snippet:-1, max-video-preview:-1 | Z9: https://pmb.widyatama.ac.id/privacy-policy/ | AF9: 178267 | AG9: 41064 | AH9: 2369801 | AI9: 840106 | AJ9: E | AK9: 1700 | AL9: 287 | AM9: 5923 | AN9: 0.000 | AO9: Very Hard | AP9: 5997 | AQ9: 1 | AR9: 1 | AT9: 107 | AU9: 77 | AV9: 2 | AW9: 88510 | AX9: 134 | AY9: 29 | AZ9: 0 | BA9: 14 | BB9: 8 | BC9: 3 | BH9: 401e2e4a0ccb7c9dda5bf523b930781a | BI9: 3159 | BJ9: Saturday, 15-Aug-2026 09:55:46 GMT | BN9: en-US | BO9: 2.0 | BQ9: https://pmb.widyatama.ac.id/privacy-policy/ | BR9: 46249.705
A10: https://pmb.widyatama.ac.id/cookie-policy/ | B10: text/html; charset=UTF-8 | C10: 200 | E10: Indexable | G10: cookie policy - PMB UTama | H10: 25 | I10: 243 | K10: 0 | L10: 0 | N10: 0 | O10: Kebijakan Cookie Website PMB Universitas Widyatama | P10: 50 | R10: 0 | S10: Cookies membantu website bekerja, tetapi pengguna tetap perlu tahu dan tetap punya kendali. | T10: 91 | U10: Empat Hal yang Perlu Anda Ketahui | V10: 33 | W10: index, follow, max-image-preview:large, max-snippet:-1, max-video-preview:-1 | Z10: https://pmb.widyatama.ac.id/cookie-policy/ | AF10: 176891 | AG10: 40040 | AH10: 2371646 | AI10: 840760 | AJ10: E | AK10: 1278 | AL10: 220 | AM10: 5809 | AN10: 0.000 | AO10: Very Hard | AP10: 4702 | AQ10: 1 | AR10: 1 | AT10: 99 | AU10: 77 | AV10: 1 | AW10: 88510 | AX10: 136 | AY10: 29 | AZ10: 1 | BA10: 12 | BB10: 8 | BC10: 3 | BH10: d062b2afab0c590f5e86ae2e3944feba | BI10: 0.111 | BJ10: Saturday, 15-Aug-2026 09:55:52 GMT | BN10: en-US | BO10: None | BQ10: https://pmb.widyatama.ac.id/cookie-policy/ | BR10: 46249.705
A11: https://pmb.widyatama.ac.id/biaya-kuliah-pascasarjana/ | B11: text/html; charset=UTF-8 | C11: 200 | E11: Indexable | G11: Biaya Kuliah Pascasarjana - PMB UTama | H11: 37 | I11: 366 | K11: 0 | L11: 0 | N11: 0 | O11: Biaya Kuliah Pascasarjana Widyatama Bandung 2026/2027 | P11: 53 | R11: 0 | S11: Biaya Pascasarjana tidak selalu dibaca dengan cara yang sama. | T11: 61 | U11: Simulasi Biaya Pascasarjana | V11: 27 | W11: index, follow, max-image-preview:large, max-snippet:-1, max-video-preview:-1 | Z11: https://pmb.widyatama.ac.id/biaya-kuliah-pascasarjana/ | AF11: 223170 | AG11: 47024 | AH11: 2345517 | AI11: 831498 | AJ11: E | AK11: 1306 | AL11: 237 | AM11: 5511 | AN11: 23038 | AO11: Very Hard | AP11: 3700 | AQ11: 1 | AR11: 1 | AT11: 333 | AU11: 77 | AV11: 76 | AW11: 88510 | AX11: 129 | AY11: 29 | AZ11: 1 | BA11: 16 | BB11: 8 | BC11: 3 | BH11: 3a62e661b9c165c6386f7c8bfde05de8 | BI11: 0.094 | BJ11: Saturday, 15-Aug-2026 09:55:53 GMT | BN11: en-US | BO11: None | BQ11: https://pmb.widyatama.ac.id/biaya-kuliah-pascasarjana/ | BR11: 46249.705
A12: https://pmb.widyatama.ac.id/mahasiswa-internasional/ | B12: text/html; charset=UTF-8 | C12: 200 | E12: Indexable | G12: Mahasiswa Internasional - PMB UTama | H12: 35 | I12: 352 | K12: 0 | L12: 0 | N12: 0 | O12: Mahasiswa Internasional Universitas Widyatama | P12: 45 | R12: 0 | S12: Siapkan dokumen akademik dan identitas sebelum memulai pendaftaran. | T12: 67 | U12: Apa yang Perlu Disiapkan Sebelum Mendaftar? | V12: 43 | W12: index, follow, max-image-preview:large, max-snippet:-1, max-video-preview:-1 | Z12: https://pmb.widyatama.ac.id/mahasiswa-internasional/ | AF12: 166543 | AG12: 37187 | AH12: 13809173 | AI12: 4895421 | AJ12: F | AK12: 668 | AL12: 142 | AM12: 4704 | AN12: 0.000 | AO12: Very Hard | AP12: 2946 | AQ12: 1 | AR12: 1 | AT12: 323 | AU12: 77 | AV12: 76 | AW12: 88510 | AX12: 132 | AY12: 31 | AZ12: 1 | BA12: 15 | BB12: 8 | BC12: 3 | BH12: c5ae0eee17e720e69e88c30d34b9438b | BI12: 0.101 | BJ12: Saturday, 15-Aug-2026 09:55:58 GMT | BN12: en-US | BO12: None | BQ12: https://pmb.widyatama.ac.id/mahasiswa-internasional/ | BR12: 46249.706
A13: https://pmb.widyatama.ac.id/output-lulusan/ | B13: text/html; charset=UTF-8 | C13: 200 | E13: Indexable | G13: Output Lulusan - PMB UTama | H13: 26 | I13: 263 | K13: 0 | L13: 0 | N13: 0 | O13: Output Lulusan Universitas Widyatama | P13: 36 | R13: 0 | S13: Halaman ini menjelaskan dokumen dan sertifikasi yang menjadi output setelah lulus. | T13: 82 | U13: Tidak Hanya Ijazah, tetapi Juga Bukti Kompetensi | V13: 48 | W13: index, follow, max-image-preview:large, max-snippet:-1, max-video-preview:-1 | Z13: https://pmb.widyatama.ac.id/output-lulusan/ | AF13: 155013 | AG13: 35332 | AH13: 2683647 | AI13: 951366 | AJ13: F | AK13: 346 | AL13: 77 | AM13: 4494 | AN13: 0.000 | AO13: Very Hard | AP13: 2056 | AQ13: 1 | AR13: 1 | AT13: 316 | AU13: 77 | AV13: 76 | AW13: 88510 | AX13: 127 | AY13: 28 | AZ13: 0 | BA13: 8 | BB13: 7 | BC13: 2 | BH13: c40c6727e76f0a4013fda4e11f1aa632 | BI13: 0.265 | BJ13: Saturday, 15-Aug-2026 09:56:08 GMT | BN13: en-US | BO13: None | BQ13: https://pmb.widyatama.ac.id/output-lulusan/ | BR13: 46249.706
A14: https://pmb.widyatama.ac.id/output-lulusan/GANTI_URL_GAMBAR_SAP | B14: text/html; charset=UTF-8 | C14: 404 | E14: Non-Indexable | F14: Client Error | H14: 0 | I14: 0 | K14: 0 | L14: 0 | N14: 0 | P14: 0 | R14: 0 | T14: 0 | V14: 0 | AF14: 0 | AG14: 40486 | AH14: 40486 | AI14: 14352 | AJ14: A+ | AK14: 0 | AP14: 0.000 | AQ14: 2 | AR14: 1 | AT14: 0 | AU14: 0 | AV14: 0 | AW14: 0.000 | AX14: 0 | AY14: 0 | AZ14: 0 | BA14: 0 | BB14: 0 | BC14: 0 | BI14: 6309 | BO14: None | BQ14: https://pmb.widyatama.ac.id/output-lulusan/GANTI_URL_GAMBAR_SAP | BR14: 46249.706
A15: https://pmb.widyatama.ac.id/output-lulusan/GANTI_URL_GAMBAR_TRANSKRIP | B15: text/html; charset=UTF-8 | C15: 404 | E15: Non-Indexable | F15: Client Error | H15: 0 | I15: 0 | K15: 0 | L15: 0 | N15: 0 | P15: 0 | R15: 0 | T15: 0 | V15: 0 | AF15: 0 | AG15: 120313 | AH15: 120313 | AI15: 42652 | AJ15: A+ | AK15: 0 | AP15: 0.000 | AQ15: 2 | AR15: 1 | AT15: 0 | AU15: 0 | AV15: 0 | AW15: 0.000 | AX15: 0 | AY15: 0 | AZ15: 0 | BA15: 0 | BB15: 0 | BC15: 0 | BI15: 4907 | BO15: None | BQ15: https://pmb.widyatama.ac.id/output-lulusan/GANTI_URL_GAMBAR_TRANSKRIP | BR15: 46249.706
A16: https://pmb.widyatama.ac.id/output-lulusan/GANTI_URL_GAMBAR_BNSP | B16: text/html; charset=UTF-8 | C16: 404 | E16: Non-Indexable | F16: Client Error | H16: 0 | I16: 0 | K16: 0 | L16: 0 | N16: 0 | P16: 0 | R16: 0 | T16: 0 | V16: 0 | AF16: 0 | AG16: 34850 | AH16: 34850 | AI16: 12354 | AJ16: A+ | AK16: 0 | AP16: 0.000 | AQ16: 2 | AR16: 1 | AT16: 0 | AU16: 0 | AV16: 0 | AW16: 0.000 | AX16: 0 | AY16: 0 | AZ16: 0 | BA16: 0 | BB16: 0 | BC16: 0 | BI16: 6139 | BO16: None | BQ16: https://pmb.widyatama.ac.id/output-lulusan/GANTI_URL_GAMBAR_BNSP | BR16: 46249.706
A17: https://pmb.widyatama.ac.id/output-lulusan/GANTI_URL_GAMBAR_IJAZAH | B17: text/html; charset=UTF-8 | C17: 404 | E17: Non-Indexable | F17: Client Error | H17: 0 | I17: 0 | K17: 0 | L17: 0 | N17: 0 | P17: 0 | R17: 0 | T17: 0 | V17: 0 | AF17: 0 | AG17: 120307 | AH17: 120307 | AI17: 42649 | AJ17: A+ | AK17: 0 | AP17: 0.000 | AQ17: 2 | AR17: 1 | AT17: 0 | AU17: 0 | AV17: 0 | AW17: 0.000 | AX17: 0 | AY17: 0 | AZ17: 0 | BA17: 0 | BB17: 0 | BC17: 0 | BI17: 4039 | BO17: None | BQ17: https://pmb.widyatama.ac.id/output-lulusan/GANTI_URL_GAMBAR_IJAZAH | BR17: 46249.706
A18: https://pmb.widyatama.ac.id/output-lulusan/GANTI_URL_GAMBAR_SKPI | B18: text/html; charset=UTF-8 | C18: 404 | E18: Non-Indexable | F18: Client Error | H18: 0 | I18: 0 | K18: 0 | L18: 0 | N18: 0 | P18: 0 | R18: 0 | T18: 0 | V18: 0 | AF18: 0 | AG18: 8123 | AH18: 8123 | AI18: 2880 | AJ18: A+ | AK18: 0 | AP18: 0.000 | AQ18: 2 | AR18: 1 | AT18: 0 | AU18: 0 | AV18: 0 | AW18: 0.000 | AX18: 0 | AY18: 0 | AZ18: 0 | BA18: 0 | BB18: 0 | BC18: 0 | BI18: 6158 | BO18: None | BQ18: https://pmb.widyatama.ac.id/output-lulusan/GANTI_URL_GAMBAR_SKPI | BR18: 46249.706
A19: https://pmb.widyatama.ac.id/beasiswa-mahasiswa-aktif/ | B19: text/html; charset=UTF-8 | C19: 200 | E19: Indexable | G19: Beasiswa Mahasiswa Aktif - PMB UTama | H19: 36 | I19: 369 | K19: 0 | L19: 0 | N19: 0 | O19: Beasiswa Mahasiswa Aktif Universitas Widyatama | P19: 46 | R19: 0 | S19: Beasiswa ini berlaku setelah calon mahasiswa resmi menjadi mahasiswa aktif. | T19: 75 | U19: Ada Peluang Beasiswa Setelah Menjadi Mahasiswa Aktif | V19: 52 | W19: index, follow, max-image-preview:large, max-snippet:-1, max-video-preview:-1 | Z19: https://pmb.widyatama.ac.id/beasiswa-mahasiswa-aktif/ | AF19: 154131 | AG19: 35009 | AH19: 2359730 | AI19: 836536 | AJ19: E | AK19: 458 | AL19: 131 | AM19: 3496 | AN19: 11366 | AO19: Very Hard | AP19: 2383 | AQ19: 1 | AR19: 1 | AT19: 316 | AU19: 77 | AV19: 76 | AW19: 88510 | AX19: 127 | AY19: 29 | AZ19: 0 | BA19: 8 | BB19: 7 | BC19: 2 | BH19: c573cedd5f4118e1c089b7888c4a266b | BI19: 0.150 | BJ19: Saturday, 15-Aug-2026 09:56:14 GMT | BN19: en-US | BO19: None | BQ19: https://pmb.widyatama.ac.id/beasiswa-mahasiswa-aktif/ | BR19: 46249.706
A20: https://pmb.widyatama.ac.id/program-rpl/ | B20: text/html; charset=UTF-8 | C20: 200 | E20: Indexable | G20: Program RPL - PMB UTama | H20: 23 | I20: 245 | K20: 0 | L20: 0 | N20: 0 | O20: Program RPL Widyatama Bandung: Rekognisi Pengalaman Kerja & Pembelajaran Lampau | P20: 79 | R20: 0 | S20: Sudah punya pengalaman kerja, pernah kuliah, atau punya sertifikasi? | T20: 68 | U20: Sudah Punya Pengalaman? Saatnya Cek Potensi Rekognisi Anda | V20: 58 | W20: index, follow, max-image-preview:large, max-snippet:-1, max-video-preview:-1 | Z20: https://pmb.widyatama.ac.id/program-rpl/ | AF20: 216360 | AG20: 45408 | AH20: 3130406 | AI20: 1109745 | AJ20: F | AK20: 1552 | AL20: 260 | AM20: 5969 | AN20: 10699 | AO20: Very Hard | AP20: 4416 | AQ20: 1 | AR20: 1 | AT20: 330 | AU20: 77 | AV20: 76 | AW20: 88510 | AX20: 160 | AY20: 51 | AZ20: 1 | BA20: 19 | BB20: 8 | BC20: 3 | BH20: e489ccee94e009b0984b4f1ce884fe0a | BI20: 0.388 | BJ20: Saturday, 15-Aug-2026 09:56:12 GMT | BN20: en-US | BO20: None | BQ20: https://pmb.widyatama.ac.id/program-rpl/ | BR20: 46249.706
A21: https://pmb.widyatama.ac.id/biaya-kuliah-kelas-karyawan/ | B21: text/html; charset=UTF-8 | C21: 200 | E21: Indexable | G21: Biaya Kuliah Kelas Karyawan - PMB UTama | H21: 39 | I21: 386 | K21: 0 | L21: 0 | N21: 0 | O21: Biaya Kuliah Kelas Karyawan Widyatama Bandung 2026/2027 | P21: 55 | R21: 0 | S21: Butuh skema biaya yang lebih mudah direncanakan? | T21: 48 | U21: Simulasi Biaya Kelas Karyawan | V21: 29 | W21: index, follow, max-image-preview:large, max-snippet:-1, max-video-preview:-1 | Z21: https://pmb.widyatama.ac.id/biaya-kuliah-kelas-karyawan/ | AF21: 228505 | AG21: 48568 | AH21: 2344527 | AI21: 831147 | AJ21: E | AK21: 1256 | AL21: 195 | AM21: 6441 | AN21: 19310 | AO21: Very Hard | AP21: 3706 | AQ21: 1 | AR21: 1 | AT21: 333 | AU21: 77 | AV21: 76 | AW21: 88510 | AX21: 130 | AY21: 29 | AZ21: 0 | BA21: 16 | BB21: 8 | BC21: 3 | BH21: d7620fe32c20cc691c4f96210da7f795 | BI21: 0.218 | BJ21: Saturday, 15-Aug-2026 09:56:16 GMT | BN21: en-US | BO21: None | BQ21: https://pmb.widyatama.ac.id/biaya-kuliah-kelas-karyawan/ | BR21: 46249.706
A22: https://pmb.widyatama.ac.id/jurusan/ | B22: text/html; charset=UTF-8 | C22: 200 | E22: Indexable | G22: Jurusan - PMB UTama | H22: 19 | I22: 201 | K22: 0 | L22: 0 | N22: 0 | O22: Daftar Jurusan di Universitas Widyatama Bandung | P22: 47 | R22: 0 | S22: Mulai dari minat, jenjang, dan prospek karier yang Anda tuju. | T22: 61 | U22: Pencarian | V22: 9 | W22: index, follow, max-image-preview:large, max-snippet:-1, max-video-preview:-1 | Z22: https://pmb.widyatama.ac.id/jurusan/ | AF22: 194593 | AG22: 41500 | AH22: 27480260 | AI22: 9741890 | AJ22: F | AK22: 526 | AL22: 172 | AM22: 3058 | AN22: 0.000 | AO22: Very Hard | AP22: 2245 | AQ22: 1 | AR22: 1 | AT22: 377 | AU22: 77 | AV22: 77 | AW22: 88510 | AX22: 167 | AY22: 80 | AZ22: 0 | BA22: 14 | BB22: 8 | BC22: 3 | BH22: cda17362fd9d8bab8f3757cbdcdfe342 | BI22: 0.224 | BJ22: Saturday, 15-Aug-2026 09:56:10 GMT | BN22: en-US | BO22: None | BQ22: https://pmb.widyatama.ac.id/jurusan/ | BR22: 46249.706
A23: https://pmb.widyatama.ac.id/blog/ | B23: text/html; charset=UTF-8 | C23: 200 | E23: Indexable | G23: Blog - PMB UTama | H23: 16 | I23: 168 | K23: 0 | L23: 0 | N23: 0 | O23: The Rapid Advancement of Digital Technology | P23: 43 | Q23: Democracy in Indonesia: Why It Feels Weak at the Grassroots | R23: 59 | S23: Search | T23: 6 | U23: Categories | V23: 10 | W23: index, follow, max-image-preview:large, max-snippet:-1, max-video-preview:-1 | Z23: https://pmb.widyatama.ac.id/blog/ | AF23: 172841 | AG23: 33714 | AH23: 2943781 | AI23: 1043585 | AJ23: F | AK23: 319 | AL23: 82 | AM23: 3890 | AN23: 70815 | AO23: Fairly Easy | AP23: 1610 | AQ23: 1 | AR23: 1 | AT23: 317 | AU23: 77 | AV23: 76 | AW23: 88510 | AX23: 149 | AY23: 39 | AZ23: 0 | BA23: 8 | BB23: 7 | BC23: 2 | BH23: 5bd6aad56c78051ff764117d1cae49cf | BI23: 0.222 | BJ23: Saturday, 15-Aug-2026 09:56:23 GMT | BN23: en-US | BO23: None | BQ23: https://pmb.widyatama.ac.id/blog/ | BR23: 46249.706
A24: https://pmb.widyatama.ac.id/biaya-kuliah-kelas-reguler/ | B24: text/html; charset=UTF-8 | C24: 200 | E24: Indexable | G24: Biaya Kuliah Kelas Reguler - PMB UTama | H24: 38 | I24: 364 | K24: 0 | L24: 0 | N24: 0 | O24: Biaya Kuliah Kelas Reguler Widyatama Bandung 2026/2027 | P24: 54 | R24: 0 | S24: Butuh memahami total biaya sebelum daftar? | T24: 42 | V24: 0 | W24: index, follow, max-image-preview:large, max-snippet:-1, max-video-preview:-1 | Z24: https://pmb.widyatama.ac.id/biaya-kuliah-kelas-reguler/ | AF24: 239794 | AG24: 50093 | AH24: 2345423 | AI24: 831464 | AJ24: E | AK24: 1937 | AL24: 622 | AM24: 3114 | AN24: 73040 | AO24: Fairly Easy | AP24: 4269 | AQ24: 1 | AR24: 1 | AT24: 362 | AU24: 77 | AV24: 77 | AW24: 88510 | AX24: 130 | AY24: 28 | AZ24: 0 | BA24: 16 | BB24: 8 | BC24: 3 | BH24: 4e1e99d197c7d1a3bbc5d241bff918be | BI24: 0.099 | BJ24: Saturday, 15-Aug-2026 09:56:28 GMT | BN24: en-US | BO24: None | BQ24: https://pmb.widyatama.ac.id/biaya-kuliah-kelas-reguler/ | BR24: 46249.706
A25: https://online.pmb.widyatama.ac.id/ | B25: text/html; charset=utf-8 | C25: 200 | E25: Indexable | G25: PMB | Universitas Widyatama | H25: 27 | I25: 262 | K25: 0 | L25: 0 | N25: 0 | O25: Program PMB | P25: 11 | R25: 0 | T25: 0 | V25: 0 | AF25: 22201 | AG25: 5693 | AH25: 963140 | AI25: 341438 | AJ25: C | AK25: 195 | AL25: 53 | AM25: 3679 | AN25: 37805 | AO25: Hard | AP25: 6433 | AQ25: 1 | AR25: 0 | AT25: 605 | AU25: 87 | AV25: 78 | AW25: 100000 | AX25: 13 | AY25: 11 | AZ25: 0 | BA25: 2 | BB25: 2 | BC25: 0 | BH25: daa80905eee0e777d0b807d8b4aafa1c | BI25: 0.251 | BN25: en | BO25: 2.0 | BQ25: https://online.pmb.widyatama.ac.id/ | BR25: 46249.706
A26: https://pmb.widyatama.ac.id/aktivitas-civitas/ | B26: text/html; charset=UTF-8 | C26: 200 | E26: Indexable | G26: Aktivitas Civitas - PMB UTama | H26: 29 | I26: 270 | K26: 0 | L26: 0 | N26: 0 | O26: The Rapid Advancement of Digital Technology | P26: 43 | Q26: Democracy in Indonesia: Why It Feels Weak at the Grassroots | R26: 59 | S26: Berbagai Aktivitas Sivitas di Universitas Widyatama | T26: 51 | U26: Fasilitas | V26: 9 | W26: index, follow, max-image-preview:large, max-snippet:-1, max-video-preview:-1 | Z26: https://pmb.widyatama.ac.id/aktivitas-civitas/ | AF26: 152369 | AG26: 32837 | AH26: 3320960 | AI26: 1177297 | AJ26: F | AK26: 162 | AL26: 44 | AM26: 3682 | AN26: 31287 | AO26: Hard | AP26: 1351 | AQ26: 1 | AR26: 1 | AT26: 320 | AU26: 77 | AV26: 76 | AW26: 88510 | AX26: 122 | AY26: 35 | AZ26: 0 | BA26: 8 | BB26: 7 | BC26: 2 | BH26: edfffc6c3beae9324d073c7621802369 | BI26: 0.101 | BJ26: Saturday, 15-Aug-2026 09:56:34 GMT | BN26: en-US | BO26: None | BQ26: https://pmb.widyatama.ac.id/aktivitas-civitas/ | BR26: 46249.706
A27: https://pmb.widyatama.ac.id/program-pascasarjana/ | B27: text/html; charset=UTF-8 | C27: 200 | E27: Indexable | G27: Program Pascasarjana - PMB UTama | H27: 32 | I27: 332 | K27: 0 | L27: 0 | N27: 0 | O27: Program Pascasarjana Widyatama Bandung untuk Pengembangan Karier, Riset, dan Kepakaran | P27: 86 | R27: 0 | S27: Masih membandingkan S2, S3, atau program profesi? | T27: 49 | U27: Mulai Langkah Studi Pascasarjana di Widyatama | V27: 45 | W27: index, follow, max-image-preview:large, max-snippet:-1, max-video-preview:-1 | Z27: https://pmb.widyatama.ac.id/program-pascasarjana/ | AF27: 197423 | AG27: 41954 | AH27: 2177616 | AI27: 771976 | AJ27: E | AK27: 1045 | AL27: 179 | AM27: 5838 | AN27: 0.000 | AO27: Very Hard | AP27: 3595 | AQ27: 1 | AR27: 1 | AT27: 325 | AU27: 77 | AV27: 76 | AW27: 88510 | AX27: 134 | AY27: 30 | AZ27: 2 | BA27: 23 | BB27: 12 | BC27: 3 | BH27: 2f64f1d152046fa82dfa3568f4e801d5 | BI27: 0.111 | BJ27: Saturday, 15-Aug-2026 09:56:37 GMT | BN27: en-US | BO27: None | BQ27: https://pmb.widyatama.ac.id/program-pascasarjana/ | BR27: 46249.706
A28: https://pmb.widyatama.ac.id/cek-jalur-pendaftaran/ | B28: text/html; charset=UTF-8 | C28: 200 | E28: Indexable | G28: Cek Jalur Pendaftaran - PMB UTama | H28: 33 | I28: 326 | K28: 0 | L28: 0 | N28: 0 | O28: Kalkulator Jalur & Beasiswa PMB Universitas Widyatama | P28: 53 | R28: 0 | S28: Gunakan hasil simulasi untuk menentukan langkah pendaftaran berikutnya. | T28: 71 | U28: Gunakan Data yang Sudah Dimiliki Calon Mahasiswa | V28: 48 | W28: index, follow, max-image-preview:large, max-snippet:-1, max-video-preview:-1 | Z28: https://pmb.widyatama.ac.id/cek-jalur-pendaftaran/ | AF28: 188679 | AG28: 42962 | AH28: 1135376 | AI28: 402496 | AJ28: C | AK28: 596 | AL28: 154 | AM28: 3870 | AN28: 3046 | AO28: Very Hard | AP28: 2370 | AQ28: 1 | AR28: 1 | AT28: 159 | AU28: 77 | AV28: 77 | AW28: 88510 | AX28: 113 | AY28: 28 | AZ28: 0 | BA28: 9 | BB28: 8 | BC28: 2 | BH28: 5190830b49f82338c8a28484ea38b206 | BI28: 2479 | BJ28: Saturday, 15-Aug-2026 09:56:46 GMT | BN28: en-US | BO28: 2.0 | BQ28: https://pmb.widyatama.ac.id/cek-jalur-pendaftaran/ | BR28: 46249.706
A29: https://pmb.widyatama.ac.id/program-reguler/ | B29: text/html; charset=UTF-8 | C29: 200 | E29: Indexable | G29: Program Reguler - PMB UTama | H29: 27 | I29: 276 | K29: 0 | L29: 0 | N29: 0 | O29: Program Reguler Widyatama Bandung: Kuliah D3, D4, dan S1 untuk Lulusan SMA/SMK/MA | P29: 81 | R29: 0 | S29: Masih bingung memilih prodi, jalur, atau estimasi biaya? | T29: 56 | U29: Mulai Rencanakan Kuliah Reguler di Widyatama | V29: 44 | W29: index, follow, max-image-preview:large, max-snippet:-1, max-video-preview:-1 | Z29: https://pmb.widyatama.ac.id/program-reguler/ | AF29: 213922 | AG29: 44908 | AH29: 2867016 | AI29: 1016372 | AJ29: F | AK29: 1433 | AL29: 254 | AM29: 5642 | AN29: 3453 | AO29: Very Hard | AP29: 4231 | AQ29: 1 | AR29: 1 | AT29: 320 | AU29: 77 | AV29: 76 | AW29: 88510 | AX29: 178 | AY29: 50 | AZ29: 0 | BA29: 19 | BB29: 8 | BC29: 3 | BH29: ee53e78bd236478123b92c94ffa2f6c9 | BI29: 0.119 | BJ29: Saturday, 15-Aug-2026 09:56:40 GMT | BN29: en-US | BO29: None | BQ29: https://pmb.widyatama.ac.id/program-reguler/ | BR29: 46249.706
A30: https://pmb.widyatama.ac.id/program-kelas-karyawan/ | B30: text/html; charset=UTF-8 | C30: 200 | E30: Indexable | G30: Program Kelas Karyawan - PMB UTama | H30: 34 | I30: 353 | K30: 0 | L30: 0 | N30: 0 | O30: Program Kelas Karyawan Widyatama Bandung untuk Kuliah Sambil Kerja | P30: 66 | R30: 0 | S30: Masih ragu jadwal kuliah cocok dengan pekerjaan Anda? | T30: 53 | U30: Mulai Langkah Naik Level Karier dengan Kelas Karyawan Widyatama | V30: 63 | W30: index, follow, max-image-preview:large, max-snippet:-1, max-video-preview:-1 | Z30: https://pmb.widyatama.ac.id/program-kelas-karyawan/ | AF30: 204815 | AG30: 42450 | AH30: 2487114 | AI30: 881694 | AJ30: F | AK30: 1636 | AL30: 300 | AM30: 5453 | AN30: 1125 | AO30: Very Hard | AP30: 4859 | AQ30: 1 | AR30: 1 | AT30: 318 | AU30: 77 | AV30: 76 | AW30: 88510 | AX30: 173 | AY30: 46 | AZ30: 0 | BA30: 23 | BB30: 9 | BC30: 4 | BH30: 16880b60e16c1d453dda67e1bcbdce3f | BI30: 1907 | BJ30: Saturday, 15-Aug-2026 09:56:49 GMT | BN30: en-US | BO30: 2.0 | BQ30: https://pmb.widyatama.ac.id/program-kelas-karyawan/ | BR30: 46249.706
A31: https://pmb.widyatama.ac.id/pengumuman-hasil-seleksi/ | B31: text/html; charset=UTF-8 | C31: 404 | E31: Non-Indexable | F31: Client Error | H31: 0 | I31: 0 | K31: 0 | L31: 0 | N31: 0 | P31: 0 | R31: 0 | T31: 0 | V31: 0 | AF31: 120632 | AG31: 28178 | AH31: 897539 | AI31: 318182 | AJ31: B | AK31: 0 | AP31: 0.000 | AQ31: 1 | AR31: 1 | AT31: 1 | AU31: 1 | AV31: 0 | AW31: 1150 | AX31: 0 | AY31: 0 | AZ31: 0 | BA31: 0 | BB31: 0 | BC31: 0 | BI31: 2671 | BO31: 2.0 | BQ31: https://pmb.widyatama.ac.id/pengumuman-hasil-seleksi/ | BR31: 46249.706
A32: https://pmb.widyatama.ac.id/fasilitas/ | B32: text/html; charset=UTF-8 | C32: 200 | E32: Indexable | G32: Fasilitas - PMB UTama | H32: 21 | I32: 203 | K32: 0 | L32: 0 | N32: 0 | O32: Fasilitas Universitas Widyatama | P32: 31 | R32: 0 | S32: Lingkungan kampus dirancang untuk mendukung belajar, berkolaborasi, dan berkembang. | T32: 83 | U32: Jelajahi Fasilitas Berdasarkan Kebutuhan | V32: 40 | W32: index, follow, max-image-preview:large, max-snippet:-1, max-video-preview:-1 | Z32: https://pmb.widyatama.ac.id/fasilitas/ | AF32: 175811 | AG32: 37161 | AH32: 25538029 | AI32: 9053359 | AJ32: F | AK32: 759 | AL32: 190 | AM32: 3995 | AN32: 0.000 | AO32: Very Hard | AP32: 3290 | AQ32: 1 | AR32: 1 | AT32: 326 | AU32: 77 | AV32: 81 | AW32: 88510 | AX32: 132 | AY32: 28 | AZ32: 0 | BA32: 8 | BB32: 7 | BC32: 2 | BH32: 31247a5ea2b419d3d9f136a97c7c14b8 | BI32: 0.954 | BJ32: Saturday, 15-Aug-2026 09:56:51 GMT | BN32: en-US | BO32: 2.0 | BQ32: https://pmb.widyatama.ac.id/fasilitas/ | BR32: 46249.706
A33: https://pmb.widyatama.ac.id/cek-kelulusan/ | B33: text/html; charset=UTF-8 | C33: 404 | E33: Non-Indexable | F33: Client Error | H33: 0 | I33: 0 | K33: 0 | L33: 0 | N33: 0 | P33: 0 | R33: 0 | T33: 0 | V33: 0 | AF33: 120610 | AG33: 28673 | AH33: 881425 | AI33: 312470 | AJ33: B | AK33: 0 | AP33: 0.000 | AQ33: 1 | AR33: 1 | AT33: 306 | AU33: 77 | AV33: 76 | AW33: 88510 | AX33: 0 | AY33: 0 | AZ33: 0 | BA33: 0 | BB33: 0 | BC33: 0 | BI33: 3525 | BO33: None | BQ33: https://pmb.widyatama.ac.id/cek-kelulusan/ | BR33: 46249.706
A34: https://pmb.widyatama.ac.id/registrasi/ | B34: text/html; charset=UTF-8 | C34: 404 | E34: Non-Indexable | F34: Client Error | H34: 0 | I34: 0 | K34: 0 | L34: 0 | N34: 0 | P34: 0 | R34: 0 | T34: 0 | V34: 0 | AF34: 120604 | AG34: 28075 | AH34: 897875 | AI34: 318301 | AJ34: B | AK34: 0 | AP34: 0.000 | AQ34: 1 | AR34: 1 | AT34: 1 | AU34: 1 | AV34: 0 | AW34: 1150 | AX34: 0 | AY34: 0 | AZ34: 0 | BA34: 0 | BB34: 0 | BC34: 0 | BI34: 2570 | BO34: 2.0 | BQ34: https://pmb.widyatama.ac.id/registrasi/ | BR34: 46249.706
A35: https://pmb.widyatama.ac.id/jalur-seleksi/ | B35: text/html; charset=UTF-8 | C35: 200 | E35: Indexable | G35: Jalur Seleksi - PMB UTama | H35: 25 | I35: 241 | K35: 0 | L35: 0 | N35: 0 | O35: Jalur Seleksi Universitas Widyatama | P35: 35 | R35: 0 | S35: Pilih jenjang dulu, lalu bandingkan jalur yang tersedia. | T35: 56 | U35: Jalur Mana yang Ingin Anda Lihat? | V35: 33 | W35: index, follow, max-image-preview:large, max-snippet:-1, max-video-preview:-1 | Z35: https://pmb.widyatama.ac.id/jalur-seleksi/ | AF35: 165035 | AG35: 36227 | AH35: 3098115 | AI35: 1098297 | AJ35: F | AK35: 504 | AL35: 114 | AM35: 4421 | AN35: 11494 | AO35: Very Hard | AP35: 2302 | AQ35: 1 | AR35: 1 | AT35: 395 | AU35: 77 | AV35: 81 | AW35: 88510 | AX35: 136 | AY35: 39 | AZ35: 0 | BA35: 15 | BB35: 8 | BC35: 3 | BH35: 7883d95a0ab8b109078fff5ef7bd12d7 | BI35: 0.077 | BJ35: Saturday, 15-Aug-2026 09:56:42 GMT | BN35: en-US | BO35: None | BQ35: https://pmb.widyatama.ac.id/jalur-seleksi/ | BR35: 46249.706
A36: https://pmb.widyatama.ac.id/biaya-kuliah-rpl/ | B36: text/html; charset=UTF-8 | C36: 200 | E36: Indexable | G36: Biaya Kuliah RPL - PMB UTama | H36: 28 | I36: 278 | K36: 0 | L36: 0 | N36: 0 | O36: Biaya Kuliah RPL Widyatama Bandung 2026/2027 | P36: 44 | R36: 0 | S36: RPL membuat biaya lebih relevan dengan SKS yang masih perlu ditempuh | T36: 68 | U36: Simulasi Biaya Program RPL | V36: 26 | W36: index, follow, max-image-preview:large, max-snippet:-1, max-video-preview:-1 | Z36: https://pmb.widyatama.ac.id/biaya-kuliah-rpl/ | AF36: 248326 | AG36: 54580 | AH36: 2441722 | AI36: 865603 | AJ36: F | AK36: 1450 | AL36: 249 | AM36: 5823 | AN36: 41118 | AO36: Hard | AP36: 3832 | AQ36: 1 | AR36: 1 | AT36: 335 | AU36: 77 | AV36: 76 | AW36: 88510 | AX36: 130 | AY36: 30 | AZ36: 1 | BA36: 16 | BB36: 8 | BC36: 3 | BH36: 31f1b50eafcdb354522e04346ff010a2 | BI36: 0.105 | BJ36: Saturday, 15-Aug-2026 09:57:10 GMT | BN36: en-US | BO36: None | BQ36: https://pmb.widyatama.ac.id/biaya-kuliah-rpl/ | BR36: 46249.706
A37: https://pmb.widyatama.ac.id/apresiasi-prestasi-mahasiswa/ | B37: text/html; charset=UTF-8 | C37: 200 | E37: Indexable | G37: Apresiasi Prestasi Mahasiswa - PMB UTama | H37: 40 | I37: 396 | K37: 0 | L37: 0 | N37: 0 | O37: Apresiasi Prestasi Mahasiswa Universitas Widyatama | P37: 50 | R37: 0 | S37: Apresiasi ini berlaku setelah mahasiswa resmi menjadi mahasiswa aktif. | T37: 70 | U37: Prestasi Mahasiswa Aktif Mendapat Ruang Apresiasi | V37: 49 | W37: index, follow, max-image-preview:large, max-snippet:-1, max-video-preview:-1 | Z37: https://pmb.widyatama.ac.id/apresiasi-prestasi-mahasiswa/ | AF37: 151958 | AG37: 34330 | AH37: 1726023 | AI37: 611884 | AJ37: D | AK37: 394 | AL37: 101 | AM37: 3901 | AN37: 0.000 | AO37: Very Hard | AP37: 2259 | AQ37: 1 | AR37: 1 | AT37: 316 | AU37: 77 | AV37: 76 | AW37: 88510 | AX37: 127 | AY37: 29 | AZ37: 0 | BA37: 8 | BB37: 7 | BC37: 2 | BH37: 51b9b0d68db4c797a121cfb6826fb407 | BI37: 1073 | BJ37: Saturday, 15-Aug-2026 09:57:44 GMT | BN37: en-US | BO37: 2.0 | BQ37: https://pmb.widyatama.ac.id/apresiasi-prestasi-mahasiswa/ | BR37: 46249.707
A38: https://pmb.widyatama.ac.id/asuransi-mahasiswa/ | B38: text/html; charset=UTF-8 | C38: 200 | E38: Indexable | G38: Asuransi Mahasiswa - PMB UTama | H38: 30 | I38: 314 | K38: 0 | L38: 0 | N38: 0 | O38: Asuransi Mahasiswa Universitas Widyatama | P38: 40 | R38: 0 | S38: Asuransi dapat dimanfaatkan ketika terjadi hal yang tidak diinginkan selama masa studi. | T38: 87 | U38: Perlindungan untuk Mahasiswa Selama Masa Studi | V38: 46 | W38: index, follow, max-image-preview:large, max-snippet:-1, max-video-preview:-1 | Z38: https://pmb.widyatama.ac.id/asuransi-mahasiswa/ | AF38: 152295 | AG38: 34118 | AH38: 2336330 | AI38: 828241 | AJ38: E | AK38: 401 | AL38: 103 | AM38: 3893 | AN38: 0.000 | AO38: Very Hard | AP38: 2239 | AQ38: 1 | AR38: 1 | AT38: 316 | AU38: 77 | AV38: 76 | AW38: 88510 | AX38: 127 | AY38: 28 | AZ38: 0 | BA38: 8 | BB38: 7 | BC38: 2 | BH38: 334fa0a13988bb75399b726be597ea7c | BI38: 0.554 | BJ38: Saturday, 15-Aug-2026 09:57:46 GMT | BN38: en-US | BO38: 2.0 | BQ38: https://pmb.widyatama.ac.id/asuransi-mahasiswa/ | BR38: 46249.707
A39: https://pmb.widyatama.ac.id/organisasi-kemahasiswaan/ | B39: text/html; charset=UTF-8 | C39: 200 | E39: Indexable | G39: Organisasi Kemahasiswaan - PMB UTama | H39: 36 | I39: 377 | K39: 0 | L39: 0 | N39: 0 | O39: UKM Paduan Suara Mahasiswa Utama PSM | P39: 36 | Q39: UKM Winner Cabaret | R39: 18 | S39: Berbagai Organisasi Kemahasiswaan di Universitas Widyatama | T39: 58 | U39: Fasilitas | V39: 9 | W39: index, follow, max-image-preview:large, max-snippet:-1, max-video-preview:-1 | Z39: https://pmb.widyatama.ac.id/organisasi-kemahasiswaan/ | AF39: 220600 | AG39: 35643 | AH39: 3481883 | AI39: 1234345 | AJ39: F | AK39: 187 | AL39: 79 | AM39: 2367 | AN39: 0.000 | AO39: Very Hard | AP39: 1164 | AQ39: 1 | AR39: 1 | AT39: 320 | AU39: 77 | AV39: 76 | AW39: 88510 | AX39: 112 | AY39: 28 | AZ39: 0 | BA39: 33 | BB39: 32 | BC39: 2 | BH39: bd54fa5c8ebf3c9246e268b55731aacb | BI39: 0.492 | BJ39: Saturday, 15-Aug-2026 09:57:49 GMT | BN39: en-US | BO39: None | BQ39: https://pmb.widyatama.ac.id/organisasi-kemahasiswaan/ | BR39: 46249.707
A40: https://pmb.widyatama.ac.id/jalur-seleksi-unggulan/ | B40: text/html; charset=UTF-8 | C40: 200 | E40: Indexable | G40: Jalur Seleksi Unggulan - PMB UTama | H40: 34 | I40: 330 | K40: 0 | L40: 0 | N40: 0 | O40: Jalur Seleksi Beasiswa Unggulan Diploma & Sarjana | P40: 49 | R40: 0 | S40: Jalur beasiswa bagi siswa dengan capaian akademik baik dan peluang seleksi yang lebih luas. | T40: 91 | U40: Jalur Unggulan Cocok untuk Calon Mahasiswa dengan Prestasi Baik dan Konsisten | V40: 77 | W40: index, follow, max-image-preview:large, max-snippet:-1, max-video-preview:-1 | Z40: https://pmb.widyatama.ac.id/jalur-seleksi-unggulan/ | AF40: 176380 | AG40: 38300 | AH40: 811056 | AI40: 287523 | AJ40: B | AK40: 809 | AL40: 164 | AM40: 4933 | AN40: 16105 | AO40: Very Hard | AP40: 3039 | AQ40: 2 | AR40: 1 | AT40: 13 | AU40: 8 | AV40: 1 | AW40: 9200 | AX40: 127 | AY40: 35 | AZ40: 0 | BA40: 16 | BB40: 8 | BC40: 3 | BH40: 1996915f334b55010d2ae4f3d9ae5f69 | BI40: 0.572 | BJ40: Saturday, 15-Aug-2026 09:57:51 GMT | BN40: en-US | BO40: None | BQ40: https://pmb.widyatama.ac.id/jalur-seleksi-unggulan/ | BR40: 46249.707
...

Sheet DATA_PROFILE
A1: HTTP Status Detail
A2: Metric | B2: Count | C2: Percentage | D2: Status Code
A3: Total HTML URLs | B3: =ROWS(tblCrawl[Address]) -> 119 | C3: =1 -> 1
A4: 200 OK | B4: =COUNTIF(tblCrawl[Status Code],D4) -> 87 | C4: =IFERROR(B4/$B$3,0) -> 0.73109244 | D4: 200
A5: 301 Permanent Redirect | B5: =COUNTIF(tblCrawl[Status Code],D5) -> 1 | C5: =IFERROR(B5/$B$3,0) -> 0.0084033613 | D5: 301
A6: 302 Temporary Redirect | B6: =COUNTIF(tblCrawl[Status Code],D6) -> 2 | C6: =IFERROR(B6/$B$3,0) -> 0.016806723 | D6: 302
A7: 403 Forbidden | B7: =COUNTIF(tblCrawl[Status Code],D7) -> 4 | C7: =IFERROR(B7/$B$3,0) -> 0.033613445 | D7: 403
A8: 404 Not Found | B8: =COUNTIF(tblCrawl[Status Code],D8) -> 25 | C8: =IFERROR(B8/$B$3,0) -> 0.21008403 | D8: 404
A10: Metric | B10: Count | C10: Percentage
A11: Total HTML URLs | B11: =ROWS(tblCrawl[Address]) -> 119 | C11: =1 -> 1
A12: Successful URLs (2xx) | B12: =COUNTIFS(tblCrawl[Status Code],">=200",tblCrawl[Status Code],"<300") -> 87 | C12: =IFERROR(B12/$B$11,0) -> 0.73109244
A13: Redirect URLs (3xx) | B13: =COUNTIFS(tblCrawl[Status Code],">=300",tblCrawl[Status Code],"<400") -> 3 | C13: =IFERROR(B13/$B$11,0) -> 0.025210084
A14: Client Error URLs (4xx) | B14: =COUNTIFS(tblCrawl[Status Code],">=400",tblCrawl[Status Code],"<500") -> 29 | C14: =IFERROR(B14/$B$11,0) -> 0.24369748
A15: Server Error URLs (5xx) | B15: =COUNTIFS(tblCrawl[Status Code],">=500",tblCrawl[Status Code],"<600") -> 0 | C15: =IFERROR(B15/$B$11,0) -> 0
X17: Based on 36 non-indexable URLs
A18: Metric | B18: Count | C18: Percentage
A19: Total HTML URLs | B19: =ROWS(tblCrawl[Address]) -> 119 | C19: =1 -> 1
A20: Indexable URLs | B20: =COUNTIF(tblCrawl[Indexability],"Indexable") -> 83 | C20: =IFERROR(B20/$B$19,0) -> 0.69747899
A21: Non-Indexable URLs | B21: =COUNTIF(tblCrawl[Indexability],"Non-Indexable") -> 36 | C21: =IFERROR(B21/$B$19,0) -> 0.30252101

Sheet CALC_HELPER
A1: Non-Indexable Reason Analysis
A2: Reason | B2: Count | C2: Percentage | E2: Non-Indexable Reason Ranking | H2: Marketing Interpretation | I2: Action Priority | J2: Short Label | K2: Action Priority | L2: Count | M2: Percentage | N2: Marketing Priority Label | O2: Display Label
A3: {=_xlfn._xlws.SORT(_xlfn.UNIQUE(_xlfn._xlws.FILTER(tblCrawl[Indexability Status],tblCrawl[Indexability]="Non-Indexable")))} -> Canonicalised | B3: {=COUNTIF(tblCrawl[Indexability Status],_xlfn.ANCHORARRAY(A3))} -> 2 | C3: {=IFERROR(_xlfn.ANCHORARRAY(B3)/SUM(_xlfn.ANCHORARRAY(B3)),0)} -> 0.055555556 | E3: {=_xlfn.LET( _xlpm.Reason,_xlfn.ANCHORARRAY(A3), _xlpm.Jumlah,_xlfn.ANCHORARRAY(B3), _xlpm.Persen,_xlfn.ANCHORARRAY(C3), _xlfn.SORTBY(_xlfn.HSTACK(_xlpm.Reason,_xlpm.Jumlah,_xlpm.Persen),_xlpm.Jumlah,-1) )} -> Client Error | F3: 29 | G3: 0.80555556 | H3: {=_xlfn.SWITCH( E3, "Client Error","Halaman tidak dapat diakses atau tidak ditemukan", "Redirected","URL mengarahkan pengunjung ke halaman lain", "Canonicalised","Halaman dianggap sebagai versi duplikat dari halaman lain", "noindex","Halaman sengaja tidak ditampilkan di hasil pencarian", "Noindex","Halaman sengaja tidak ditampilkan di hasil pencarian", "Blocked by robots.txt","Akses mesin pencari ke halaman dibatasi", "Perlu pemeriksaan teknis lebih lanjut" )} -> Halaman tidak dapat diakses atau tidak ditemukan | I3: {=_xlfn.SWITCH( E3, "Client Error","Priority 1 - Validate/Fix", "Redirected","Priority 2 - Review", "Canonicalised","Priority 2 - Review", "noindex","Expected / Verify", "Noindex","Expected / Verify", "Blocked by robots.txt","Expected / Verify", "Technical Review" )} -> Priority 1 - Validate/Fix | J3: Halaman Tidak Dapat Diakses | K3: {=_xlfn._xlws.SORT(_xlfn.UNIQUE(_xlfn._xlws.FILTER(I3:I12,I3:I12<>"")))} -> Expected / Verify | L3: {=SUMIF($I$3:$I$12,_xlfn.ANCHORARRAY(K3),$F$3:$F$12)} -> 2 | M3: {=IFERROR(_xlfn.ANCHORARRAY(L3)/SUM(_xlfn.ANCHORARRAY(L3)),0)} -> 0.055555556 | N3: {=_xlfn.SWITCH( K3, "Priority 1 - Validate/Fix","Perlu Ditangani Lebih Dulu", "Priority 2 - Review","Perlu Ditinjau", "Expected / Verify","Perlu Diverifikasi", "Technical Review","Perlu Review Teknis", "Perlu Ditinjau" )} -> Perlu Diverifikasi | O3: {=_xlfn.ANCHORARRAY(L3)&" URL ("&TEXT(_xlfn.ANCHORARRAY(M3),"0,00%")&")"} -> 2 URL (5,56%)
A4: Client Error | B4: 29 | C4: 0.80555556 | E4: Redirected | F4: 3 | G4: 0.083333333 | H4: {=_xlfn.SWITCH( E4, "Client Error","Halaman tidak dapat diakses atau tidak ditemukan", "Redirected","URL mengarahkan pengunjung ke halaman lain", "Canonicalised","Halaman dianggap sebagai versi duplikat dari halaman lain", "noindex","Halaman sengaja tidak ditampilkan di hasil pencarian", "Noindex","Halaman sengaja tidak ditampilkan di hasil pencarian", "Blocked by robots.txt","Akses mesin pencari ke halaman dibatasi", "Perlu pemeriksaan teknis lebih lanjut" )} -> URL mengarahkan pengunjung ke halaman lain | I4: {=_xlfn.SWITCH( E4, "Client Error","Priority 1 - Validate/Fix", "Redirected","Priority 2 - Review", "Canonicalised","Priority 2 - Review", "noindex","Expected / Verify", "Noindex","Expected / Verify", "Blocked by robots.txt","Expected / Verify", "Technical Review" )} -> Priority 2 - Review | J4: Redirect ke Halaman Lain | K4: Priority 1 - Validate/Fix | L4: 29 | M4: 0.80555556 | N4: {=_xlfn.SWITCH( K4, "Priority 1 - Validate/Fix","Perlu Ditangani Lebih Dulu", "Priority 2 - Review","Perlu Ditinjau", "Expected / Verify","Perlu Diverifikasi", "Technical Review","Perlu Review Teknis", "Perlu Ditinjau" )} -> Perlu Ditangani Lebih Dulu | O4: 29 URL (80,56%)
A5: noindex | B5: 2 | C5: 0.055555556 | E5: Canonicalised | F5: 2 | G5: 0.055555556 | H5: {=_xlfn.SWITCH( E5, "Client Error","Halaman tidak dapat diakses atau tidak ditemukan", "Redirected","URL mengarahkan pengunjung ke halaman lain", "Canonicalised","Halaman dianggap sebagai versi duplikat dari halaman lain", "noindex","Halaman sengaja tidak ditampilkan di hasil pencarian", "Noindex","Halaman sengaja tidak ditampilkan di hasil pencarian", "Blocked by robots.txt","Akses mesin pencari ke halaman dibatasi", "Perlu pemeriksaan teknis lebih lanjut" )} -> Halaman dianggap sebagai versi duplikat dari halaman lain | I5: {=_xlfn.SWITCH( E5, "Client Error","Priority 1 - Validate/Fix", "Redirected","Priority 2 - Review", "Canonicalised","Priority 2 - Review", "noindex","Expected / Verify", "Noindex","Expected / Verify", "Blocked by robots.txt","Expected / Verify", "Technical Review" )} -> Priority 2 - Review | J5: Halaman Duplikat | K5: Priority 2 - Review | L5: 5 | M5: 0.13888889 | N5: {=_xlfn.SWITCH( K5, "Priority 1 - Validate/Fix","Perlu Ditangani Lebih Dulu", "Priority 2 - Review","Perlu Ditinjau", "Expected / Verify","Perlu Diverifikasi", "Technical Review","Perlu Review Teknis", "Perlu Ditinjau" )} -> Perlu Ditinjau | O5: 5 URL (13,89%)
A6: Redirected | B6: 3 | C6: 0.083333333 | E6: noindex | F6: 2 | G6: 0.055555556 | H6: {=_xlfn.SWITCH( E6, "Client Error","Halaman tidak dapat diakses atau tidak ditemukan", "Redirected","URL mengarahkan pengunjung ke halaman lain", "Canonicalised","Halaman dianggap sebagai versi duplikat dari halaman lain", "noindex","Halaman sengaja tidak ditampilkan di hasil pencarian", "Noindex","Halaman sengaja tidak ditampilkan di hasil pencarian", "Blocked by robots.txt","Akses mesin pencari ke halaman dibatasi", "Perlu pemeriksaan teknis lebih lanjut" )} -> Halaman sengaja tidak ditampilkan di hasil pencarian | I6: {=_xlfn.SWITCH( E6, "Client Error","Priority 1 - Validate/Fix", "Redirected","Priority 2 - Review", "Canonicalised","Priority 2 - Review", "noindex","Expected / Verify", "Noindex","Expected / Verify", "Blocked by robots.txt","Expected / Verify", "Technical Review" )} -> Expected / Verify | J6: Tidak Ditampilkan di Pencarian | L6: =SUM(_xlfn.ANCHORARRAY(L3)) -> 36 | M6: =SUM(_xlfn.ANCHORARRAY(M3)) -> 1
B7: =SUM(_xlfn.ANCHORARRAY(B3)) -> 36 | C7: =SUM(_xlfn.ANCHORARRAY(C3)) -> 1

Sheet DASHBOARD_EXCEL
A1: WEBSITE PMB WIDYATAMA — WEBSITE HEALTH
A41: Initial Website Crawl Assessment — 119 Internal HTML URLs

Sheet PAGE_INVENTORY
A1: {=tblCrawl[#Headers]} -> Address | B1: Content Type | C1: Status Code | D1: Status | E1: Indexability | F1: Indexability Status | G1: Title 1 | H1: Title 1 Length | I1: Title 1 Pixel Width | J1: Meta Description 1 | K1: Meta Description 1 Length | L1: Meta Description 1 Pixel Width | M1: Meta Keywords 1 | N1: Meta Keywords 1 Length | O1: H1-1 | P1: H1-1 Length | Q1: H1-2 | R1: H1-2 Length | S1: H2-1 | T1: H2-1 Length | U1: H2-2 | V1: H2-2 Length | W1: Meta Robots 1 | X1: X-Robots-Tag 1 | Y1: Meta Refresh 1 | Z1: Canonical Link Element 1 | AA1: rel="next" 1 | AB1: rel="prev" 1 | AC1: HTTP rel="next" 1 | AD1: HTTP rel="prev" 1 | AE1: amphtml Link Element | AF1: Size (bytes) | AG1: Transferred (bytes) | AH1: Total Transferred (bytes) | AI1: CO2 (mg) | AJ1: Carbon Rating | AK1: Word Count | AL1: Sentence Count | AM1: Average Words Per Sentence | AN1: Flesch Reading Ease Score | AO1: Readability | AP1: Text Ratio | AQ1: Crawl Depth | AR1: Folder Depth | AS1: Link Score | AT1: Inlinks | AU1: Unique Inlinks | AV1: Unique JS Inlinks | AW1: % of Total | AX1: Outlinks | AY1: Unique Outlinks | AZ1: Unique JS Outlinks | BA1: External Outlinks | BB1: Unique External Outlinks | BC1: Unique External JS Outlinks | BD1: Closest Similarity Match | BE1: No. Near Duplicates | BF1: Spelling Errors | BG1: Grammar Errors | BH1: Hash | BI1: Response Time | BJ1: Last Modified | BK1: Redirect URL | BL1: Redirect Type | BM1: Cookies | BN1: Language | BO1: HTTP Version | BP1: Mobile Alternate Link | BQ1: URL Encoded Address | BR1: Crawl Timestamp | BT1: Metric | BU1: Count | BV1: Percentage | BZ1: URL | CA1: Indexability | CB1: Indexability Status | CC1: Page Type | CD1: Site Scope | CE1: Include Speed Test | CF1: Page Type | CG1: Count | CH1: Percentage | CI1: Other URLs | CJ1: Other Count | CK1: First Slug | CL1: Site Scope | CM1: Count | CO1: First Slug Summary | CP1: Count | CQ1: Refined Page Type | CS1: Refined Page Type Summary | CT1: URL Count | CU1: Percentage | CV1: Final Page Type | CW1: Final Page Type Summary | CX1: Count | CY1: Percentage | DA1: Other Review URLs | DB1: Site Scope | DC1: Indexability | DD1: First Slug | DE1: Second Slug | DF1: Resolved Page Type | DG1: Final Page Type v2 | DI1: Final Page Type Summary | DJ1: Count | DK1: Percentage | DM1: Content Review URLs | DN1: Site Scope | DO1: Indexability | DP1: Page Title | DQ1: Content Relevance Status | DS1: Content Relevance Summary | DT1: Count | DU1: Percentage | DV1: Speed Test Segment | DW1: Include Speed Test | DX1: Speed Test Segment | DY1: Count | DZ1: Percentage | EA1: Test Priority | EC1: Test Priority Summary | ED1: Count | EE1: Percentage
A2: {=_xlfn._xlws.FILTER(tblCrawl[],tblCrawl[Status Code]=200,"Tidak ada URL 200")} -> https://pmb.widyatama.ac.id/ | B2: text/html; charset=UTF-8 | C2: 200 | D2: 0 | E2: Indexable | F2: 0 | G2: Home - PMB UTama | H2: 16 | I2: 182 | J2: 0 | K2: 0 | L2: 0 | M2: 0 | N2: 0 | O2: Penerimaan Mahasiswa Baru Universitas Widyatama Bandung | P2: 55 | Q2: 0 | R2: 0 | S2: Temukan Jalur Kuliah yang Paling Sesuai | T2: 39 | U2: Program Studi Diploma, Sarjana, dan Pascasarjana | V2: 48 | W2: index, follow, max-image-preview:large, max-snippet:-1, max-video-preview:-1 | X2: 0 | Y2: 0 | Z2: https://pmb.widyatama.ac.id/ | AA2: 0 | AB2: 0 | AC2: 0 | AD2: 0 | AE2: 0 | AF2: 222241 | AG2: 46607 | AH2: 37100272 | AI2: 13152232 | AJ2: F | AK2: 961 | AL2: 199 | AM2: 4829 | AN2: 0.000 | AO2: Very Hard | AP2: 3528 | AQ2: 0 | AR2: 0 | AS2: 0 | AT2: 466 | AU2: 77 | AV2: 77 | AW2: 88510 | AX2: 128 | AY2: 32 | AZ2: 0 | BA2: 21 | BB2: 12 | BC2: 4 | BD2: 0 | BE2: 0 | BF2: 0 | BG2: 0 | BH2: a20e81bc6438e5cebb62cebec82d43c2 | BI2: 3290 | BJ2: Saturday, 15-Aug-2026 09:54:51 GMT | BK2: 0 | BL2: 0 | BM2: 0 | BN2: en-US | BO2: 2.0 | BP2: 0 | BQ2: https://pmb.widyatama.ac.id/ | BR2: 46249.705 | BT2: Active URLs (200) | BU2: =COUNTIF(tblCrawl[Status Code],200) -> 87 | BV2: =1 -> 1 | BZ2: {=_xlfn._xlws.FILTER(tblCrawl[Address],tblCrawl[Status Code]=200,"")} -> https://pmb.widyatama.ac.id/ | CA2: {=_xlfn._xlws.FILTER(tblCrawl[Indexability],tblCrawl[Status Code]=200,"")} -> Indexable | CB2: {=_xlfn._xlws.FILTER(tblCrawl[Indexability Status],tblCrawl[Status Code]=200,"")} -> 0 | CC2: {=_xlfn.LET( _xlpm.u,LOWER(_xlfn.ANCHORARRAY(BZ2)), IF( _xlpm.u="https://pmb.widyatama.ac.id/", "Homepage", IF( ISNUMBER(SEARCH("/biaya",_xlpm.u)), "Pricing", IF( (ISNUMBER(SEARCH("/program",_xlpm.u))+ISNUMBER(SEARCH("/jurusan",_xlpm.u)))>0, "Program", IF( (ISNUMBER(SEARCH("/jalur",_xlpm.u))+ISNUMBER(SEARCH("/seleksi",_xlpm.u))+ISNUMBER(SEARCH("/pendaftaran",_xlpm.u)))>0, "Admission", IF( (ISNUMBER(SEARCH("/beasiswa",_xlpm.u))+ISNUMBER(SEARCH("/campaign",_xlpm.u))+ISNUMBER(SEARCH("/promo",_xlpm.u)))>0, "Campaign", IF( (ISNUMBER(SEARCH("/berita",_xlpm.u))+ISNUMBER(SEARCH("/artikel",_xlpm.u))+ISNUMBER(SEARCH("/news",_xlpm.u)))>0, "Content", "Other" ) ) ) ) ) ) )} -> Homepage | CD2: {=IF( ISNUMBER(SEARCH("online.pmb.widyatama.ac.id",_xlfn.ANCHORARRAY(BZ2))), "Online Registration System", "Main PMB Website" )} -> Main PMB Website | CE2: {=IF((_xlfn.ANCHORARRAY(CD2)="Main PMB Website")+(_xlfn.ANCHORARRAY(CD2)="Online Registration System"),"Yes","Review")} -> Yes | CF2: {=_xlfn._xlws.SORT(_xlfn.UNIQUE(_xlfn.ANCHORARRAY(CC2)))} -> Admission | CG2: =COUNTIF(_xlfn.ANCHORARRAY(CC2),CF2) -> 13 | CH2: =IFERROR(CG2/SUM($CG$2:$CG$7),0) -> 0.14942529 | CI2: {=_xlfn._xlws.FILTER(_xlfn.ANCHORARRAY(BZ2),_xlfn.ANCHORARRAY(CC2)="Other","Tidak ada URL Other")} -> https://pmb.widyatama.ac.id/petunjuk-pendaftaran/ | CJ2: =ROWS(_xlfn.ANCHORARRAY(CI2)) -> 39 | CK2: {=_xlfn.LET( _xlpm.path,_xlfn.TEXTAFTER(_xlfn.ANCHORARRAY(CI2),"/",3), IF(_xlpm.path="","Homepage/System Root",_xlfn.TEXTBEFORE(_xlpm.path&"/","/")) )} -> petunjuk-pendaftaran | CL2: {=_xlfn._xlws.SORT(_xlfn.UNIQUE(_xlfn.ANCHORARRAY(CD2)))} -> Main PMB Website | CM2: =COUNTIF(_xlfn.ANCHORARRAY(CD2),CL2) -> 77 | CO2: {=_xlfn._xlws.SORT(_xlfn.UNIQUE(_xlfn.ANCHORARRAY(CK2)))} -> 2025 | CP2: =COUNTIF(_xlfn.ANCHORARRAY($CK$2),CO2) -> 2 | CQ2: {=_xlfn.LET( _xlpm.s,LOWER(CO2), _xlfn.SWITCH( TRUE, OR(_xlpm.s="petunjuk-pendaftaran",_xlpm.s="cek-jalur-pendaftaran"),"Admission", OR(_xlpm.s="jenjang-pendidikan",_xlpm.s="output-lulusan"),"Information", OR(_xlpm.s="privacy-policy",_xlpm.s="cookie-policy"),"Policy", _xlpm.s="mahasiswa-internasional","International", OR( _xlpm.s="aktivitas-civitas", _xlpm.s="fasilitas", _xlpm.s="apresiasi-prestasi-mahasiswa", _xlpm.s="asuransi-mahasiswa", _xlpm.s="organisasi-kemahasiswaan" ),"Campus Life", OR( _xlpm.s="register", _xlpm.s="auth", _xlpm.s="homepage/system root" ),"Registration System", _xlpm.s="blog","Content", OR( ISNUMBER(SEARCH("democracy-in-indonesia",_xlpm.s)), ISNUMBER(SEARCH("hidden-dangers-of-sugar",_xlpm.s)), ISNUMBER(SEARCH("rapid-advancement-of-digital-technology",_xlpm.s)), _xlpm.s="2025" ),"Content Review", "Other Review" ) )} -> Content Review | CS2: {=_xlfn._xlws.SORT(_xlfn.UNIQUE(_xlfn._xlws.FILTER(CQ2:CQ100,CQ2:CQ100<>"")))} -> Admission | CT2: =SUMIF($CQ$2:$CQ$100,CS2,$CP$2:$CP$100) -> 2 | CU2: =IFERROR(CT2/SUM($CT$2:$CT$20),0) -> 0.051282051 | CV2: {=_xlfn.LET( _xlpm.u,_xlfn.ANCHORARRAY(BZ2), _xlpm.initial,_xlfn.ANCHORARRAY(CC2), _xlpm.path,IFERROR(_xlfn.TEXTAFTER(_xlpm.u,"/",3),""), _xlpm.slug,IF(_xlpm.path="","Homepage/System Root",_xlfn.TEXTBEFORE(_xlpm.path&"/","/")), IF( _xlpm.initial<>"Other", _xlpm.initial, _xlfn.XLOOKUP(_xlpm.slug,$CO$2:$CO$100,$CQ$2:$CQ$100,"Other Review") ) )} -> Homepage | CW2: {=_xlfn._xlws.SORT(_xlfn.UNIQUE(_xlfn.ANCHORARRAY(CV2)))} -> Admission | CX2: =COUNTIF(_xlfn.ANCHORARRAY($CV$2),CW2) -> 15 | CY2: =IFERROR(CX2/ROWS(_xlfn.ANCHORARRAY($CV$2)),0) -> 0.17241379 | DA2: {=_xlfn._xlws.FILTER(_xlfn.ANCHORARRAY(BZ2),_xlfn.ANCHORARRAY(CV2)="Other Review","Tidak ada Other Review")} -> https://online.pmb.widyatama.ac.id/hasil | DB2: {=_xlfn._xlws.FILTER(_xlfn.ANCHORARRAY(CD2),_xlfn.ANCHORARRAY(CV2)="Other Review","")} -> Online Registration System | DC2: {=_xlfn._xlws.FILTER(_xlfn.ANCHORARRAY(CA2),_xlfn.ANCHORARRAY(CV2)="Other Review","")} -> Indexable | DD2: {=_xlfn.LET( _xlpm.path,_xlfn.TEXTAFTER(_xlfn.ANCHORARRAY(DA2),"/",3), IF(_xlpm.path="","Homepage/System Root",_xlfn.TEXTBEFORE(_xlpm.path&"/","/")) )} -> hasil | DE2: {=_xlfn.LET( _xlpm.path,_xlfn.TEXTAFTER(_xlfn.ANCHORARRAY(DA2),"/",3), _xlpm.rest,IFERROR(_xlfn.TEXTAFTER(_xlpm.path,"/"),""), IF(_xlpm.rest="","(none)",_xlfn.TEXTBEFORE(_xlpm.rest&"/","/")) )} -> (none) | DF2: {=IF(_xlfn.ANCHORARRAY( DB2)="Online Registration System", "Registration System", IF(_xlfn.ANCHORARRAY( DD2)="category", "Content Archive", "Other Review" ) )} -> Registration System | DG2: {=_xlfn.LET( _xlpm.u,_xlfn.ANCHORARRAY(BZ2), _xlpm.current,_xlfn.ANCHORARRAY(CV2), IF( _xlpm.current<>"Other Review", _xlpm.current, _xlfn.XLOOKUP(_xlpm.u,_xlfn.ANCHORARRAY(DA2),_xlfn.ANCHORARRAY(DF2),"Other Review") ) )} -> Homepage | DI2: {=_xlfn._xlws.SORT(_xlfn.UNIQUE(_xlfn.ANCHORARRAY(DG2)))} -> Admission | DJ2: =COUNTIF(_xlfn.ANCHORARRAY($DG$2),DI2) -> 15 | DK2: =IFERROR(DJ2/ROWS(_xlfn.ANCHORARRAY($DG$2)),0) -> 0.17241379 | DM2: {=_xlfn._xlws.FILTER(_xlfn.ANCHORARRAY(BZ2),_xlfn.ANCHORARRAY(DG2)="Content Review","Tidak ada Content Review")} -> https://pmb.widyatama.ac.id/democracy-in-indonesia-why-it-feels-weak-at-the-grassroots/ | DN2: {=_xlfn._xlws.FILTER(_xlfn.ANCHORARRAY(CD2),_xlfn.ANCHORARRAY(DG2)="Content Review","")} -> Main PMB Website | DO2: {=_xlfn._xlws.FILTER(_xlfn.ANCHORARRAY(CA2),_xlfn.ANCHORARRAY(DG2)="Content Review","")} -> Indexable | DQ2: {=_xlfn.LET( _xlpm.txt,LOWER(_xlfn.ANCHORARRAY(DM2)&" "&_xlfn.ANCHORARRAY(DP2)), IF( ( ISNUMBER(SEARCH("democracy-in-indonesia",_xlpm.txt))+ ISNUMBER(SEARCH("hidden-dangers-of-sugar",_xlpm.txt))+ ISNUMBER(SEARCH("rapid-advancement-of-digital-technology",_xlpm.txt)) )>0, "Likely Irrelevant to PMB", IF( ( ISNUMBER(SEARCH("pmb",_xlpm.txt))+ ISNUMBER(SEARCH("pendaftaran",_xlpm.txt))+ ISNUMBER(SEARCH("beasiswa",_xlpm.txt))+ ISNUMBER(SEARCH("program",_xlpm.txt))+ ISNUMBER(SEARCH("jurusan",_xlpm.txt))+ ISNUMBER(SEARCH("mahasiswa",_xlpm.txt))+ ISNUMBER(SEARCH("widyatama",_xlpm.txt)) )>0, "Likely Relevant to PMB", "Needs Manual Review" ) ) )} -> Needs Manual Review | DS2: {=_xlfn._xlws.SORT(_xlfn.UNIQUE(_xlfn._xlws.FILTER(DQ2:DQ100,DQ2:DQ100<>"")))} -> Needs Manual Review | DT2: =COUNTIF($DQ$2:$DQ$100,DS2) -> 11 | DU2: =IFERROR(DT2/SUM($DT$2:$DT$10),0) -> 1 | DV2: {=_xlfn.LET( _xlpm.scope,_xlfn.ANCHORARRAY(CD2), _xlpm.ptype,_xlfn.ANCHORARRAY(DG2), IF( _xlpm.ptype="Content Review", "Content Audit", IF( _xlpm.scope="Online Registration System", "Registration System", "Core PMB Website" ) ) )} -> Core PMB Website | DW2: {=IF(_xlfn.ANCHORARRAY(DV2)<>"","Yes","Review")} -> Yes | DX2: {=_xlfn._xlws.SORT(_xlfn.UNIQUE(_xlfn.ANCHORARRAY(DV2)))} -> Content Audit | DY2: =COUNTIF(_xlfn.ANCHORARRAY($DV$2),DX2) -> 11 | DZ2: =IFERROR(DY2/ROWS(_xlfn.ANCHORARRAY($DV$2)),0) -> 0.12643678 | EA2: {=_xlfn.LET( _xlpm.pt,_xlfn.ANCHORARRAY(DG2), _xlpm.seg,_xlfn.ANCHORARRAY(DV2), IF( _xlpm.seg="Content Audit", "P4 - Content Audit", IF( ((_xlpm.pt="Homepage")+(_xlpm.pt="Admission")+(_xlpm.pt="Pricing")+(_xlpm.pt="Program")+(_xlpm.pt="Registration System"))>0, "P1 - Critical", IF( ((_xlpm.pt="Campaign")+(_xlpm.pt="International")+(_xlpm.pt="Information")+(_xlpm.pt="Campus Life"))>0, "P2 - High", "P3 - Standard" ) ) ) )} -> P1 - Critical | EC2: {=_xlfn._xlws.SORT(_xlfn.UNIQUE(_xlfn.ANCHORARRAY(EA2)))} -> P1 - Critical | ED2: =COUNTIF(_xlfn.ANCHORARRAY($EA$2),EC2) -> 59 | EE2: =IFERROR(ED2/ROWS(_xlfn.ANCHORARRAY($EA$2)),0) -> 0.67816092
A3: https://pmb.widyatama.ac.id/petunjuk-pendaftaran/ | B3: text/html; charset=UTF-8 | C3: 200 | D3: 0 | E3: Indexable | F3: 0 | G3: Petunjuk Pendaftaran - PMB UTama | H3: 32 | I3: 322 | J3: 0 | K3: 0 | L3: 0 | M3: 0 | N3: 0 | O3: Petunjuk Pendaftaran Mahasiswa Baru Universitas Widyatama | P3: 57 | Q3: 0 | R3: 0 | S3: Buat akun PMB lebih dulu, lalu ikuti setiap tahap dengan urut. | T3: 62 | U3: Cara Mudah Daftar Kuliah Online | V3: 31 | W3: index, follow, max-image-preview:large, max-snippet:-1, max-video-preview:-1 | X3: 0 | Y3: 0 | Z3: https://pmb.widyatama.ac.id/petunjuk-pendaftaran/ | AA3: 0 | AB3: 0 | AC3: 0 | AD3: 0 | AE3: 0 | AF3: 175545 | AG3: 38335 | AH3: 3734312 | AI3: 1323832 | AJ3: F | AK3: 943 | AL3: 197 | AM3: 4787 | AN3: 13847 | AO3: Very Hard | AP3: 3382 | AQ3: 1 | AR3: 1 | AS3: 0 | AT3: 334 | AU3: 77 | AV3: 80 | AW3: 88510 | AX3: 139 | AY3: 30 | AZ3: 1 | BA3: 17 | BB3: 9 | BC3: 4 | BD3: 0 | BE3: 0 | BF3: 0 | BG3: 0 | BH3: a2d3f3de39b760ce0970219c23bc52b8 | BI3: 0.098 | BJ3: Saturday, 15-Aug-2026 09:55:42 GMT | BK3: 0 | BL3: 0 | BM3: 0 | BN3: en-US | BO3: None | BP3: 0 | BQ3: https://pmb.widyatama.ac.id/petunjuk-pendaftaran/ | BR3: 46249.705 | BT3: 200 + Indexable | BU3: =COUNTIFS(tblCrawl[Status Code],200,tblCrawl[Indexability],"Indexable") -> 83 | BV3: =IFERROR(BU3/$BU$2,0) -> 0.95402299 | BZ3: https://pmb.widyatama.ac.id/petunjuk-pendaftaran/ | CA3: Indexable | CB3: 0 | CC3: Other | CD3: Main PMB Website | CE3: Yes | CF3: Campaign | CG3: =COUNTIF(_xlfn.ANCHORARRAY(CC2),CF3) -> 1 | CH3: =IFERROR(CG3/SUM($CG$2:$CG$7),0) -> 0.011494253 | CI3: https://pmb.widyatama.ac.id/jenjang-pendidikan/ | CK3: jenjang-pendidikan | CL3: Online Registration System | CM3: =COUNTIF(_xlfn.ANCHORARRAY($CD$2),CL3) -> 10 | CO3: aktivitas-civitas | CP3: =COUNTIF(_xlfn.ANCHORARRAY($CK$2),CO3) -> 3 | CQ3: {=_xlfn.LET( _xlpm.s,LOWER(CO3), _xlfn.SWITCH( TRUE, OR(_xlpm.s="petunjuk-pendaftaran",_xlpm.s="cek-jalur-pendaftaran"),"Admission", OR(_xlpm.s="jenjang-pendidikan",_xlpm.s="output-lulusan"),"Information", OR(_xlpm.s="privacy-policy",_xlpm.s="cookie-policy"),"Policy", _xlpm.s="mahasiswa-internasional","International", OR( _xlpm.s="aktivitas-civitas", _xlpm.s="fasilitas", _xlpm.s="apresiasi-prestasi-mahasiswa", _xlpm.s="asuransi-mahasiswa", _xlpm.s="organisasi-kemahasiswaan" ),"Campus Life", OR( _xlpm.s="register", _xlpm.s="auth", _xlpm.s="homepage/system root" ),"Registration System", _xlpm.s="blog","Content", OR( ISNUMBER(SEARCH("democracy-in-indonesia",_xlpm.s)), ISNUMBER(SEARCH("hidden-dangers-of-sugar",_xlpm.s)), ISNUMBER(SEARCH("rapid-advancement-of-digital-technology",_xlpm.s)), _xlpm.s="2025" ),"Content Review", "Other Review" ) )} -> Campus Life | CS3: Campus Life | CT3: =SUMIF($CQ$2:$CQ$100,CS3,$CP$2:$CP$100) -> 7 | CU3: =IFERROR(CT3/SUM($CT$2:$CT$20),0) -> 0.17948718 | CV3: Admission | CW3: Campaign | CX3: =COUNTIF(_xlfn.ANCHORARRAY($CV$2),CW3) -> 1 | CY3: =IFERROR(CX3/ROWS(_xlfn.ANCHORARRAY($CV$2)),0) -> 0.011494253 | DA3: https://pmb.widyatama.ac.id/category/science-and-technology/ | DB3: Main PMB Website | DC3: Indexable | DD3: category | DE3: science-and-technology | DF3: Content Archive | DG3: Admission | DI3: Campaign | DJ3: =COUNTIF(_xlfn.ANCHORARRAY($DG$2),DI3) -> 1 | DK3: =IFERROR(DJ3/ROWS(_xlfn.ANCHORARRAY($DG$2)),0) -> 0.011494253 | DM3: https://pmb.widyatama.ac.id/2025/09/19/ | DN3: Main PMB Website | DO3: Non-Indexable | DQ3: Needs Manual Review | DV3: Core PMB Website | DW3: Yes | DX3: Core PMB Website | DY3: =COUNTIF(_xlfn.ANCHORARRAY($DV$2),DX3) -> 66 | DZ3: =IFERROR(DY3/ROWS(_xlfn.ANCHORARRAY($DV$2)),0) -> 0.75862069 | EA3: P1 - Critical | EC3: P2 - High | ED3: =COUNTIF(_xlfn.ANCHORARRAY($EA$2),EC3) -> 11 | EE3: =IFERROR(ED3/ROWS(_xlfn.ANCHORARRAY($EA$2)),0) -> 0.12643678
